package test;

public class ExpectionTest {

    boolean testEx() throws Exception {
        boolean ret = true;
        try {
            ret = testEx1();
        } catch (Exception e) {
            System.out.println("testEx, catch exception");
            ret = false;
            throw e;
        } finally {
            System.out.println("testEx, finally; return value=" + ret);
            return ret;
        }
    }

    boolean testEx1() throws Exception {
        boolean ret = true;
        try {
            ret = testEx2();
            if (!ret) {
                return false;
            }
            System.out.println("testEx1, at the end of try");
            return ret;
        } catch (Exception e) {
            System.out.println("testEx1, catch exception");
            ret = false;
            throw e;
        } finally {
            System.out.println("testEx1, finally; return value=" + ret);
            return ret;
        }
    }

    boolean testEx2() throws Exception {
        boolean ret = true;
        try {
            int b = 12;
            int c;
            for (int i = 2; i >= -2; i--) {
                c = b / i;
                System.out.println("i=" + i);
            }
            return true;
        } catch (Exception e) {
            System.out.println("testEx2, catch exception");
            e.printStackTrace();
            ret = false;
            throw e;
        } finally {
            System.out.println("testEx2, finally; return value=" + ret);
            return ret;
        }
    }

    public static void main(String[] args) {
        int a = 6;
        int b = 0;
        try { // try监控区域

            if (b == 0) throw new ArithmeticException(); // 通过throw语句抛出异常
            System.out.println("a/b的值是：" + a / b);
        }
        catch (ArithmeticException e) { // catch捕捉异常
            System.out.println("程序出现异常，变量b不能为0。");
        }
        System.out.println("程序正常结束。");
    }
}
